üöÄ Phase 4B Îç∞Î™® ÏãúÏûë
============================================================

üîç ÏóêÎü¨ Î™®Îç∏ Îç∞Î™®
==================================================
‚úÖ Ï†ïÏÉÅ ÏºÄÏù¥Ïä§: ÏÑ±Í≥µ (valid=False)
‚ùå ValidationError (ÏùåÏàò): ValidationError - negative not allowed
‚ö†Ô∏è  TransientError (ÌÉÄÏûÑÏïÑÏõÉ): TransientError - simulated timeout
üí• SystemError (ÏãúÏä§ÌÖú Ïò§Î•ò): SystemError - simulated system error

üîÑ Î¶¨Ìä∏ÎùºÏù¥ Ï†ïÏ±Ö Îç∞Î™®
==================================================
Î¶¨Ìä∏ÎùºÏù¥ ÏÑ§Ï†ï: ÏµúÎåÄ 2Ìöå, Î∞±Ïò§ÌîÑ [2, 8]ms, ÏßÄÌÑ∞ 3ms

üöÄ ÏãúÎÇòÎ¶¨Ïò§ Ïã§Ìñâ: 50Í∞ú ÏöîÏ≤≠, ÎèôÏãúÏÑ± 5
2025-08-10 21:21:19,992 ERROR core.runner_engine :: [system-fail-unexpected] req_id=4 attempt=1 elapsed_ms=10.5 err=TransientError() takes no keyword arguments
Traceback (most recent call last):
  File "/home/duri/DuRiWorkspace/DuRiCore/adapters/mock/mock_validator.py", line 149, in validate
    return await super().validate(request_id, data)
  File "/home/duri/DuRiWorkspace/DuRiCore/adapters/mock/mock_validator.py", line 69, in validate
    await asyncio.sleep(latency_ms / 1000.0)  # Convert to seconds
  File "/usr/lib/python3.10/asyncio/tasks.py", line 605, in sleep
    return await future
asyncio.exceptions.CancelledError

During handling of the above exception, another exception occurred:

Traceback (most recent call last):
  File "/usr/lib/python3.10/asyncio/tasks.py", line 456, in wait_for
    return fut.result()
asyncio.exceptions.CancelledError

The above exception was the direct cause of the following exception:

Traceback (most recent call last):
  File "/home/duri/DuRiWorkspace/DuRiCore/core/runner_engine.py", line 23, in _attempt_once
    return await asyncio.wait_for(self.validator.validate(request_id, payload), timeout=per_attempt)
  File "/usr/lib/python3.10/asyncio/tasks.py", line 458, in wait_for
    raise exceptions.TimeoutError() from exc
asyncio.exceptions.TimeoutError

During handling of the above exception, another exception occurred:

Traceback (most recent call last):
  File "/home/duri/DuRiWorkspace/DuRiCore/core/runner_engine.py", line 40, in _validate_with_retry
    res = await self._attempt_once(request_id, payload)
  File "/home/duri/DuRiWorkspace/DuRiCore/core/runner_engine.py", line 26, in _attempt_once
    raise TransientError("timeout", code="timeout") from e
TypeError: TransientError() takes no keyword arguments
2025-08-10 21:21:19,992 ERROR core.runner_engine :: [system-fail-unexpected] req_id=0 attempt=1 elapsed_ms=10.9 err=TransientError() takes no keyword arguments
Traceback (most recent call last):
  File "/home/duri/DuRiWorkspace/DuRiCore/adapters/mock/mock_validator.py", line 149, in validate
    return await super().validate(request_id, data)
  File "/home/duri/DuRiWorkspace/DuRiCore/adapters/mock/mock_validator.py", line 69, in validate
    await asyncio.sleep(latency_ms / 1000.0)  # Convert to seconds
  File "/usr/lib/python3.10/asyncio/tasks.py", line 605, in sleep
    return await future
asyncio.exceptions.CancelledError

During handling of the above exception, another exception occurred:

Traceback (most recent call last):
  File "/usr/lib/python3.10/asyncio/tasks.py", line 456, in wait_for
    return fut.result()
asyncio.exceptions.CancelledError

The above exception was the direct cause of the following exception:

Traceback (most recent call last):
  File "/home/duri/DuRiWorkspace/DuRiCore/core/runner_engine.py", line 23, in _attempt_once
    return await asyncio.wait_for(self.validator.validate(request_id, payload), timeout=per_attempt)
  File "/usr/lib/python3.10/asyncio/tasks.py", line 458, in wait_for
    raise exceptions.TimeoutError() from exc
asyncio.exceptions.TimeoutError

During handling of the above exception, another exception occurred:

Traceback (most recent call last):
  File "/home/duri/DuRiWorkspace/DuRiCore/core/runner_engine.py", line 40, in _validate_with_retry
    res = await self._attempt_once(request_id, payload)
  File "/home/duri/DuRiWorkspace/DuRiCore/core/runner_engine.py", line 26, in _attempt_once
    raise TransientError("timeout", code="timeout") from e
TypeError: TransientError() takes no keyword arguments
2025-08-10 21:21:20,001 ERROR core.runner_engine :: [system-fail-unexpected] req_id=6 attempt=1 elapsed_ms=10.1 err=TransientError() takes no keyword arguments
Traceback (most recent call last):
  File "/home/duri/DuRiWorkspace/DuRiCore/adapters/mock/mock_validator.py", line 149, in validate
    return await super().validate(request_id, data)
  File "/home/duri/DuRiWorkspace/DuRiCore/adapters/mock/mock_validator.py", line 69, in validate
    await asyncio.sleep(latency_ms / 1000.0)  # Convert to seconds
  File "/usr/lib/python3.10/asyncio/tasks.py", line 605, in sleep
    return await future
asyncio.exceptions.CancelledError

During handling of the above exception, another exception occurred:

Traceback (most recent call last):
  File "/usr/lib/python3.10/asyncio/tasks.py", line 456, in wait_for
    return fut.result()
asyncio.exceptions.CancelledError

The above exception was the direct cause of the following exception:

Traceback (most recent call last):
  File "/home/duri/DuRiWorkspace/DuRiCore/core/runner_engine.py", line 23, in _attempt_once
    return await asyncio.wait_for(self.validator.validate(request_id, payload), timeout=per_attempt)
  File "/usr/lib/python3.10/asyncio/tasks.py", line 458, in wait_for
    raise exceptions.TimeoutError() from exc
asyncio.exceptions.TimeoutError

During handling of the above exception, another exception occurred:

Traceback (most recent call last):
  File "/home/duri/DuRiWorkspace/DuRiCore/core/runner_engine.py", line 40, in _validate_with_retry
    res = await self._attempt_once(request_id, payload)
  File "/home/duri/DuRiWorkspace/DuRiCore/core/runner_engine.py", line 26, in _attempt_once
    raise TransientError("timeout", code="timeout") from e
TypeError: TransientError() takes no keyword arguments
2025-08-10 21:21:20,005 ERROR core.runner_engine :: [system-fail-unexpected] req_id=10 attempt=1 elapsed_ms=10.9 err=TransientError() takes no keyword arguments
Traceback (most recent call last):
  File "/home/duri/DuRiWorkspace/DuRiCore/adapters/mock/mock_validator.py", line 149, in validate
    return await super().validate(request_id, data)
  File "/home/duri/DuRiWorkspace/DuRiCore/adapters/mock/mock_validator.py", line 69, in validate
    await asyncio.sleep(latency_ms / 1000.0)  # Convert to seconds
  File "/usr/lib/python3.10/asyncio/tasks.py", line 605, in sleep
    return await future
asyncio.exceptions.CancelledError

During handling of the above exception, another exception occurred:

Traceback (most recent call last):
  File "/usr/lib/python3.10/asyncio/tasks.py", line 456, in wait_for
    return fut.result()
asyncio.exceptions.CancelledError

The above exception was the direct cause of the following exception:

Traceback (most recent call last):
  File "/home/duri/DuRiWorkspace/DuRiCore/core/runner_engine.py", line 23, in _attempt_once
    return await asyncio.wait_for(self.validator.validate(request_id, payload), timeout=per_attempt)
  File "/usr/lib/python3.10/asyncio/tasks.py", line 458, in wait_for
    raise exceptions.TimeoutError() from exc
asyncio.exceptions.TimeoutError

During handling of the above exception, another exception occurred:

Traceback (most recent call last):
  File "/home/duri/DuRiWorkspace/DuRiCore/core/runner_engine.py", line 40, in _validate_with_retry
    res = await self._attempt_once(request_id, payload)
  File "/home/duri/DuRiWorkspace/DuRiCore/core/runner_engine.py", line 26, in _attempt_once
    raise TransientError("timeout", code="timeout") from e
TypeError: TransientError() takes no keyword arguments
2025-08-10 21:21:20,008 ERROR core.runner_engine :: [system-fail-unexpected] req_id=12 attempt=1 elapsed_ms=11.0 err=TransientError() takes no keyword arguments
Traceback (most recent call last):
  File "/home/duri/DuRiWorkspace/DuRiCore/adapters/mock/mock_validator.py", line 149, in validate
    return await super().validate(request_id, data)
  File "/home/duri/DuRiWorkspace/DuRiCore/adapters/mock/mock_validator.py", line 69, in validate
    await asyncio.sleep(latency_ms / 1000.0)  # Convert to seconds
  File "/usr/lib/python3.10/asyncio/tasks.py", line 605, in sleep
    return await future
asyncio.exceptions.CancelledError

During handling of the above exception, another exception occurred:

Traceback (most recent call last):
  File "/usr/lib/python3.10/asyncio/tasks.py", line 456, in wait_for
    return fut.result()
asyncio.exceptions.CancelledError

The above exception was the direct cause of the following exception:

Traceback (most recent call last):
  File "/home/duri/DuRiWorkspace/DuRiCore/core/runner_engine.py", line 23, in _attempt_once
    return await asyncio.wait_for(self.validator.validate(request_id, payload), timeout=per_attempt)
  File "/usr/lib/python3.10/asyncio/tasks.py", line 458, in wait_for
    raise exceptions.TimeoutError() from exc
asyncio.exceptions.TimeoutError

During handling of the above exception, another exception occurred:

Traceback (most recent call last):
  File "/home/duri/DuRiWorkspace/DuRiCore/core/runner_engine.py", line 40, in _validate_with_retry
    res = await self._attempt_once(request_id, payload)
  File "/home/duri/DuRiWorkspace/DuRiCore/core/runner_engine.py", line 26, in _attempt_once
    raise TransientError("timeout", code="timeout") from e
TypeError: TransientError() takes no keyword arguments
2025-08-10 21:21:20,010 ERROR core.runner_engine :: [system-fail-unexpected] req_id=13 attempt=1 elapsed_ms=10.2 err=TransientError() takes no keyword arguments
Traceback (most recent call last):
  File "/home/duri/DuRiWorkspace/DuRiCore/adapters/mock/mock_validator.py", line 149, in validate
    return await super().validate(request_id, data)
  File "/home/duri/DuRiWorkspace/DuRiCore/adapters/mock/mock_validator.py", line 69, in validate
    await asyncio.sleep(latency_ms / 1000.0)  # Convert to seconds
  File "/usr/lib/python3.10/asyncio/tasks.py", line 605, in sleep
    return await future
asyncio.exceptions.CancelledError

During handling of the above exception, another exception occurred:

Traceback (most recent call last):
  File "/usr/lib/python3.10/asyncio/tasks.py", line 456, in wait_for
    return fut.result()
asyncio.exceptions.CancelledError

The above exception was the direct cause of the following exception:

Traceback (most recent call last):
  File "/home/duri/DuRiWorkspace/DuRiCore/core/runner_engine.py", line 23, in _attempt_once
    return await asyncio.wait_for(self.validator.validate(request_id, payload), timeout=per_attempt)
  File "/usr/lib/python3.10/asyncio/tasks.py", line 458, in wait_for
    raise exceptions.TimeoutError() from exc
asyncio.exceptions.TimeoutError

During handling of the above exception, another exception occurred:

Traceback (most recent call last):
  File "/home/duri/DuRiWorkspace/DuRiCore/core/runner_engine.py", line 40, in _validate_with_retry
    res = await self._attempt_once(request_id, payload)
  File "/home/duri/DuRiWorkspace/DuRiCore/core/runner_engine.py", line 26, in _attempt_once
    raise TransientError("timeout", code="timeout") from e
TypeError: TransientError() takes no keyword arguments
2025-08-10 21:21:20,021 ERROR core.runner_engine :: [system-fail-unexpected] req_id=18 attempt=1 elapsed_ms=10.7 err=TransientError() takes no keyword arguments
Traceback (most recent call last):
  File "/home/duri/DuRiWorkspace/DuRiCore/adapters/mock/mock_validator.py", line 149, in validate
    return await super().validate(request_id, data)
  File "/home/duri/DuRiWorkspace/DuRiCore/adapters/mock/mock_validator.py", line 69, in validate
    await asyncio.sleep(latency_ms / 1000.0)  # Convert to seconds
  File "/usr/lib/python3.10/asyncio/tasks.py", line 605, in sleep
    return await future
asyncio.exceptions.CancelledError

During handling of the above exception, another exception occurred:

Traceback (most recent call last):
  File "/usr/lib/python3.10/asyncio/tasks.py", line 456, in wait_for
    return fut.result()
asyncio.exceptions.CancelledError

The above exception was the direct cause of the following exception:

Traceback (most recent call last):
  File "/home/duri/DuRiWorkspace/DuRiCore/core/runner_engine.py", line 23, in _attempt_once
    return await asyncio.wait_for(self.validator.validate(request_id, payload), timeout=per_attempt)
  File "/usr/lib/python3.10/asyncio/tasks.py", line 458, in wait_for
    raise exceptions.TimeoutError() from exc
asyncio.exceptions.TimeoutError

During handling of the above exception, another exception occurred:

Traceback (most recent call last):
  File "/home/duri/DuRiWorkspace/DuRiCore/core/runner_engine.py", line 40, in _validate_with_retry
    res = await self._attempt_once(request_id, payload)
  File "/home/duri/DuRiWorkspace/DuRiCore/core/runner_engine.py", line 26, in _attempt_once
    raise TransientError("timeout", code="timeout") from e
TypeError: TransientError() takes no keyword arguments
2025-08-10 21:21:20,021 ERROR core.runner_engine :: [system-fail-unexpected] req_id=19 attempt=1 elapsed_ms=10.7 err=TransientError() takes no keyword arguments
Traceback (most recent call last):
  File "/home/duri/DuRiWorkspace/DuRiCore/adapters/mock/mock_validator.py", line 149, in validate
    return await super().validate(request_id, data)
  File "/home/duri/DuRiWorkspace/DuRiCore/adapters/mock/mock_validator.py", line 69, in validate
    await asyncio.sleep(latency_ms / 1000.0)  # Convert to seconds
  File "/usr/lib/python3.10/asyncio/tasks.py", line 605, in sleep
    return await future
asyncio.exceptions.CancelledError

During handling of the above exception, another exception occurred:

Traceback (most recent call last):
  File "/usr/lib/python3.10/asyncio/tasks.py", line 456, in wait_for
    return fut.result()
asyncio.exceptions.CancelledError

The above exception was the direct cause of the following exception:

Traceback (most recent call last):
  File "/home/duri/DuRiWorkspace/DuRiCore/core/runner_engine.py", line 23, in _attempt_once
    return await asyncio.wait_for(self.validator.validate(request_id, payload), timeout=per_attempt)
  File "/usr/lib/python3.10/asyncio/tasks.py", line 458, in wait_for
    raise exceptions.TimeoutError() from exc
asyncio.exceptions.TimeoutError

During handling of the above exception, another exception occurred:

Traceback (most recent call last):
  File "/home/duri/DuRiWorkspace/DuRiCore/core/runner_engine.py", line 40, in _validate_with_retry
    res = await self._attempt_once(request_id, payload)
  File "/home/duri/DuRiWorkspace/DuRiCore/core/runner_engine.py", line 26, in _attempt_once
    raise TransientError("timeout", code="timeout") from e
TypeError: TransientError() takes no keyword arguments
2025-08-10 21:21:20,024 ERROR core.runner_engine :: [system-fail-unexpected] req_id=20 attempt=1 elapsed_ms=10.9 err=TransientError() takes no keyword arguments
Traceback (most recent call last):
  File "/home/duri/DuRiWorkspace/DuRiCore/adapters/mock/mock_validator.py", line 149, in validate
    return await super().validate(request_id, data)
  File "/home/duri/DuRiWorkspace/DuRiCore/adapters/mock/mock_validator.py", line 69, in validate
    await asyncio.sleep(latency_ms / 1000.0)  # Convert to seconds
  File "/usr/lib/python3.10/asyncio/tasks.py", line 605, in sleep
    return await future
asyncio.exceptions.CancelledError

During handling of the above exception, another exception occurred:

Traceback (most recent call last):
  File "/usr/lib/python3.10/asyncio/tasks.py", line 456, in wait_for
    return fut.result()
asyncio.exceptions.CancelledError

The above exception was the direct cause of the following exception:

Traceback (most recent call last):
  File "/home/duri/DuRiWorkspace/DuRiCore/core/runner_engine.py", line 23, in _attempt_once
    return await asyncio.wait_for(self.validator.validate(request_id, payload), timeout=per_attempt)
  File "/usr/lib/python3.10/asyncio/tasks.py", line 458, in wait_for
    raise exceptions.TimeoutError() from exc
asyncio.exceptions.TimeoutError

During handling of the above exception, another exception occurred:

Traceback (most recent call last):
  File "/home/duri/DuRiWorkspace/DuRiCore/core/runner_engine.py", line 40, in _validate_with_retry
    res = await self._attempt_once(request_id, payload)
  File "/home/duri/DuRiWorkspace/DuRiCore/core/runner_engine.py", line 26, in _attempt_once
    raise TransientError("timeout", code="timeout") from e
TypeError: TransientError() takes no keyword arguments
2025-08-10 21:21:20,031 ERROR core.runner_engine :: [system-fail-unexpected] req_id=23 attempt=1 elapsed_ms=10.6 err=TransientError() takes no keyword arguments
Traceback (most recent call last):
  File "/home/duri/DuRiWorkspace/DuRiCore/adapters/mock/mock_validator.py", line 149, in validate
    return await super().validate(request_id, data)
  File "/home/duri/DuRiWorkspace/DuRiCore/adapters/mock/mock_validator.py", line 69, in validate
    await asyncio.sleep(latency_ms / 1000.0)  # Convert to seconds
  File "/usr/lib/python3.10/asyncio/tasks.py", line 605, in sleep
    return await future
asyncio.exceptions.CancelledError

During handling of the above exception, another exception occurred:

Traceback (most recent call last):
  File "/usr/lib/python3.10/asyncio/tasks.py", line 456, in wait_for
    return fut.result()
asyncio.exceptions.CancelledError

The above exception was the direct cause of the following exception:

Traceback (most recent call last):
  File "/home/duri/DuRiWorkspace/DuRiCore/core/runner_engine.py", line 23, in _attempt_once
    return await asyncio.wait_for(self.validator.validate(request_id, payload), timeout=per_attempt)
  File "/usr/lib/python3.10/asyncio/tasks.py", line 458, in wait_for
    raise exceptions.TimeoutError() from exc
asyncio.exceptions.TimeoutError

During handling of the above exception, another exception occurred:

Traceback (most recent call last):
  File "/home/duri/DuRiWorkspace/DuRiCore/core/runner_engine.py", line 40, in _validate_with_retry
    res = await self._attempt_once(request_id, payload)
  File "/home/duri/DuRiWorkspace/DuRiCore/core/runner_engine.py", line 26, in _attempt_once
    raise TransientError("timeout", code="timeout") from e
TypeError: TransientError() takes no keyword arguments
2025-08-10 21:21:20,032 ERROR core.runner_engine :: [system-fail-unexpected] req_id=24 attempt=1 elapsed_ms=10.7 err=TransientError() takes no keyword arguments
Traceback (most recent call last):
  File "/home/duri/DuRiWorkspace/DuRiCore/adapters/mock/mock_validator.py", line 149, in validate
    return await super().validate(request_id, data)
  File "/home/duri/DuRiWorkspace/DuRiCore/adapters/mock/mock_validator.py", line 69, in validate
    await asyncio.sleep(latency_ms / 1000.0)  # Convert to seconds
  File "/usr/lib/python3.10/asyncio/tasks.py", line 605, in sleep
    return await future
asyncio.exceptions.CancelledError

During handling of the above exception, another exception occurred:

Traceback (most recent call last):
  File "/usr/lib/python3.10/asyncio/tasks.py", line 456, in wait_for
    return fut.result()
asyncio.exceptions.CancelledError

The above exception was the direct cause of the following exception:

Traceback (most recent call last):
  File "/home/duri/DuRiWorkspace/DuRiCore/core/runner_engine.py", line 23, in _attempt_once
    return await asyncio.wait_for(self.validator.validate(request_id, payload), timeout=per_attempt)
  File "/usr/lib/python3.10/asyncio/tasks.py", line 458, in wait_for
    raise exceptions.TimeoutError() from exc
asyncio.exceptions.TimeoutError

During handling of the above exception, another exception occurred:

Traceback (most recent call last):
  File "/home/duri/DuRiWorkspace/DuRiCore/core/runner_engine.py", line 40, in _validate_with_retry
    res = await self._attempt_once(request_id, payload)
  File "/home/duri/DuRiWorkspace/DuRiCore/core/runner_engine.py", line 26, in _attempt_once
    raise TransientError("timeout", code="timeout") from e
TypeError: TransientError() takes no keyword arguments
2025-08-10 21:21:20,042 ERROR core.runner_engine :: [system-fail-unexpected] req_id=28 attempt=1 elapsed_ms=10.6 err=TransientError() takes no keyword arguments
Traceback (most recent call last):
  File "/home/duri/DuRiWorkspace/DuRiCore/adapters/mock/mock_validator.py", line 149, in validate
    return await super().validate(request_id, data)
  File "/home/duri/DuRiWorkspace/DuRiCore/adapters/mock/mock_validator.py", line 69, in validate
    await asyncio.sleep(latency_ms / 1000.0)  # Convert to seconds
  File "/usr/lib/python3.10/asyncio/tasks.py", line 605, in sleep
    return await future
asyncio.exceptions.CancelledError

During handling of the above exception, another exception occurred:

Traceback (most recent call last):
  File "/usr/lib/python3.10/asyncio/tasks.py", line 456, in wait_for
    return fut.result()
asyncio.exceptions.CancelledError

The above exception was the direct cause of the following exception:

Traceback (most recent call last):
  File "/home/duri/DuRiWorkspace/DuRiCore/core/runner_engine.py", line 23, in _attempt_once
    return await asyncio.wait_for(self.validator.validate(request_id, payload), timeout=per_attempt)
  File "/usr/lib/python3.10/asyncio/tasks.py", line 458, in wait_for
    raise exceptions.TimeoutError() from exc
asyncio.exceptions.TimeoutError

During handling of the above exception, another exception occurred:

Traceback (most recent call last):
  File "/home/duri/DuRiWorkspace/DuRiCore/core/runner_engine.py", line 40, in _validate_with_retry
    res = await self._attempt_once(request_id, payload)
  File "/home/duri/DuRiWorkspace/DuRiCore/core/runner_engine.py", line 26, in _attempt_once
    raise TransientError("timeout", code="timeout") from e
TypeError: TransientError() takes no keyword arguments
2025-08-10 21:21:20,043 ERROR core.runner_engine :: [system-fail-unexpected] req_id=31 attempt=1 elapsed_ms=10.6 err=TransientError() takes no keyword arguments
Traceback (most recent call last):
  File "/home/duri/DuRiWorkspace/DuRiCore/adapters/mock/mock_validator.py", line 149, in validate
    return await super().validate(request_id, data)
  File "/home/duri/DuRiWorkspace/DuRiCore/adapters/mock/mock_validator.py", line 69, in validate
    await asyncio.sleep(latency_ms / 1000.0)  # Convert to seconds
  File "/usr/lib/python3.10/asyncio/tasks.py", line 605, in sleep
    return await future
asyncio.exceptions.CancelledError

During handling of the above exception, another exception occurred:

Traceback (most recent call last):
  File "/usr/lib/python3.10/asyncio/tasks.py", line 456, in wait_for
    return fut.result()
asyncio.exceptions.CancelledError

The above exception was the direct cause of the following exception:

Traceback (most recent call last):
  File "/home/duri/DuRiWorkspace/DuRiCore/core/runner_engine.py", line 23, in _attempt_once
    return await asyncio.wait_for(self.validator.validate(request_id, payload), timeout=per_attempt)
  File "/usr/lib/python3.10/asyncio/tasks.py", line 458, in wait_for
    raise exceptions.TimeoutError() from exc
asyncio.exceptions.TimeoutError

During handling of the above exception, another exception occurred:

Traceback (most recent call last):
  File "/home/duri/DuRiWorkspace/DuRiCore/core/runner_engine.py", line 40, in _validate_with_retry
    res = await self._attempt_once(request_id, payload)
  File "/home/duri/DuRiWorkspace/DuRiCore/core/runner_engine.py", line 26, in _attempt_once
    raise TransientError("timeout", code="timeout") from e
TypeError: TransientError() takes no keyword arguments
2025-08-10 21:21:20,058 ERROR core.runner_engine :: [system-fail-unexpected] req_id=37 attempt=1 elapsed_ms=10.6 err=TransientError() takes no keyword arguments
Traceback (most recent call last):
  File "/home/duri/DuRiWorkspace/DuRiCore/adapters/mock/mock_validator.py", line 149, in validate
    return await super().validate(request_id, data)
  File "/home/duri/DuRiWorkspace/DuRiCore/adapters/mock/mock_validator.py", line 69, in validate
    await asyncio.sleep(latency_ms / 1000.0)  # Convert to seconds
  File "/usr/lib/python3.10/asyncio/tasks.py", line 605, in sleep
    return await future
asyncio.exceptions.CancelledError

During handling of the above exception, another exception occurred:

Traceback (most recent call last):
  File "/usr/lib/python3.10/asyncio/tasks.py", line 456, in wait_for
    return fut.result()
asyncio.exceptions.CancelledError

The above exception was the direct cause of the following exception:

Traceback (most recent call last):
  File "/home/duri/DuRiWorkspace/DuRiCore/core/runner_engine.py", line 23, in _attempt_once
    return await asyncio.wait_for(self.validator.validate(request_id, payload), timeout=per_attempt)
  File "/usr/lib/python3.10/asyncio/tasks.py", line 458, in wait_for
    raise exceptions.TimeoutError() from exc
asyncio.exceptions.TimeoutError

During handling of the above exception, another exception occurred:

Traceback (most recent call last):
  File "/home/duri/DuRiWorkspace/DuRiCore/core/runner_engine.py", line 40, in _validate_with_retry
    res = await self._attempt_once(request_id, payload)
  File "/home/duri/DuRiWorkspace/DuRiCore/core/runner_engine.py", line 26, in _attempt_once
    raise TransientError("timeout", code="timeout") from e
TypeError: TransientError() takes no keyword arguments
2025-08-10 21:21:20,061 ERROR core.runner_engine :: [system-fail-unexpected] req_id=39 attempt=1 elapsed_ms=10.8 err=TransientError() takes no keyword arguments
Traceback (most recent call last):
  File "/home/duri/DuRiWorkspace/DuRiCore/adapters/mock/mock_validator.py", line 149, in validate
    return await super().validate(request_id, data)
  File "/home/duri/DuRiWorkspace/DuRiCore/adapters/mock/mock_validator.py", line 69, in validate
    await asyncio.sleep(latency_ms / 1000.0)  # Convert to seconds
  File "/usr/lib/python3.10/asyncio/tasks.py", line 605, in sleep
    return await future
asyncio.exceptions.CancelledError

During handling of the above exception, another exception occurred:

Traceback (most recent call last):
  File "/usr/lib/python3.10/asyncio/tasks.py", line 456, in wait_for
    return fut.result()
asyncio.exceptions.CancelledError

The above exception was the direct cause of the following exception:

Traceback (most recent call last):
  File "/home/duri/DuRiWorkspace/DuRiCore/core/runner_engine.py", line 23, in _attempt_once
    return await asyncio.wait_for(self.validator.validate(request_id, payload), timeout=per_attempt)
  File "/usr/lib/python3.10/asyncio/tasks.py", line 458, in wait_for
    raise exceptions.TimeoutError() from exc
asyncio.exceptions.TimeoutError

During handling of the above exception, another exception occurred:

Traceback (most recent call last):
  File "/home/duri/DuRiWorkspace/DuRiCore/core/runner_engine.py", line 40, in _validate_with_retry
    res = await self._attempt_once(request_id, payload)
  File "/home/duri/DuRiWorkspace/DuRiCore/core/runner_engine.py", line 26, in _attempt_once
    raise TransientError("timeout", code="timeout") from e
TypeError: TransientError() takes no keyword arguments
2025-08-10 21:21:20,061 ERROR core.runner_engine :: [system-fail-unexpected] req_id=41 attempt=1 elapsed_ms=10.9 err=TransientError() takes no keyword arguments
Traceback (most recent call last):
  File "/home/duri/DuRiWorkspace/DuRiCore/adapters/mock/mock_validator.py", line 149, in validate
    return await super().validate(request_id, data)
  File "/home/duri/DuRiWorkspace/DuRiCore/adapters/mock/mock_validator.py", line 69, in validate
    await asyncio.sleep(latency_ms / 1000.0)  # Convert to seconds
  File "/usr/lib/python3.10/asyncio/tasks.py", line 605, in sleep
    return await future
asyncio.exceptions.CancelledError

During handling of the above exception, another exception occurred:

Traceback (most recent call last):
  File "/usr/lib/python3.10/asyncio/tasks.py", line 456, in wait_for
    return fut.result()
asyncio.exceptions.CancelledError

The above exception was the direct cause of the following exception:

Traceback (most recent call last):
  File "/home/duri/DuRiWorkspace/DuRiCore/core/runner_engine.py", line 23, in _attempt_once
    return await asyncio.wait_for(self.validator.validate(request_id, payload), timeout=per_attempt)
  File "/usr/lib/python3.10/asyncio/tasks.py", line 458, in wait_for
    raise exceptions.TimeoutError() from exc
asyncio.exceptions.TimeoutError

During handling of the above exception, another exception occurred:

Traceback (most recent call last):
  File "/home/duri/DuRiWorkspace/DuRiCore/core/runner_engine.py", line 40, in _validate_with_retry
    res = await self._attempt_once(request_id, payload)
  File "/home/duri/DuRiWorkspace/DuRiCore/core/runner_engine.py", line 26, in _attempt_once
    raise TransientError("timeout", code="timeout") from e
TypeError: TransientError() takes no keyword arguments
2025-08-10 21:21:20,068 ERROR core.runner_engine :: [system-fail-unexpected] req_id=43 attempt=1 elapsed_ms=11.0 err=TransientError() takes no keyword arguments
Traceback (most recent call last):
  File "/home/duri/DuRiWorkspace/DuRiCore/adapters/mock/mock_validator.py", line 149, in validate
    return await super().validate(request_id, data)
  File "/home/duri/DuRiWorkspace/DuRiCore/adapters/mock/mock_validator.py", line 69, in validate
    await asyncio.sleep(latency_ms / 1000.0)  # Convert to seconds
  File "/usr/lib/python3.10/asyncio/tasks.py", line 605, in sleep
    return await future
asyncio.exceptions.CancelledError

During handling of the above exception, another exception occurred:

Traceback (most recent call last):
  File "/usr/lib/python3.10/asyncio/tasks.py", line 456, in wait_for
    return fut.result()
asyncio.exceptions.CancelledError

The above exception was the direct cause of the following exception:

Traceback (most recent call last):
  File "/home/duri/DuRiWorkspace/DuRiCore/core/runner_engine.py", line 23, in _attempt_once
    return await asyncio.wait_for(self.validator.validate(request_id, payload), timeout=per_attempt)
  File "/usr/lib/python3.10/asyncio/tasks.py", line 458, in wait_for
    raise exceptions.TimeoutError() from exc
asyncio.exceptions.TimeoutError

During handling of the above exception, another exception occurred:

Traceback (most recent call last):
  File "/home/duri/DuRiWorkspace/DuRiCore/core/runner_engine.py", line 40, in _validate_with_retry
    res = await self._attempt_once(request_id, payload)
  File "/home/duri/DuRiWorkspace/DuRiCore/core/runner_engine.py", line 26, in _attempt_once
    raise TransientError("timeout", code="timeout") from e
TypeError: TransientError() takes no keyword arguments
2025-08-10 21:21:20,077 ERROR core.runner_engine :: [system-fail-unexpected] req_id=48 attempt=1 elapsed_ms=10.6 err=TransientError() takes no keyword arguments
Traceback (most recent call last):
  File "/home/duri/DuRiWorkspace/DuRiCore/adapters/mock/mock_validator.py", line 149, in validate
    return await super().validate(request_id, data)
  File "/home/duri/DuRiWorkspace/DuRiCore/adapters/mock/mock_validator.py", line 69, in validate
    await asyncio.sleep(latency_ms / 1000.0)  # Convert to seconds
  File "/usr/lib/python3.10/asyncio/tasks.py", line 605, in sleep
    return await future
asyncio.exceptions.CancelledError

During handling of the above exception, another exception occurred:

Traceback (most recent call last):
  File "/usr/lib/python3.10/asyncio/tasks.py", line 456, in wait_for
    return fut.result()
asyncio.exceptions.CancelledError

The above exception was the direct cause of the following exception:

Traceback (most recent call last):
  File "/home/duri/DuRiWorkspace/DuRiCore/core/runner_engine.py", line 23, in _attempt_once
    return await asyncio.wait_for(self.validator.validate(request_id, payload), timeout=per_attempt)
  File "/usr/lib/python3.10/asyncio/tasks.py", line 458, in wait_for
    raise exceptions.TimeoutError() from exc
asyncio.exceptions.TimeoutError

During handling of the above exception, another exception occurred:

Traceback (most recent call last):
  File "/home/duri/DuRiWorkspace/DuRiCore/core/runner_engine.py", line 40, in _validate_with_retry
    res = await self._attempt_once(request_id, payload)
  File "/home/duri/DuRiWorkspace/DuRiCore/core/runner_engine.py", line 26, in _attempt_once
    raise TransientError("timeout", code="timeout") from e
TypeError: TransientError() takes no keyword arguments

üìä Í≤∞Í≥º ÏöîÏïΩ:
   Ï¥ù ÏöîÏ≤≠: 50
   ÏÑ±Í≥µ: 32
   Ïã§Ìå®: 18
   Ï†ÑÏ≤¥ ÏÑ±Í≥µÎ•†: 0.640
   Í∞ÄÏö©ÏÑ± ÏÑ±Í≥µÎ•†(Validation Ï†úÏô∏): 0.640
   p95 ÏßÄÏó∞: 10.95ms
   Ï≤òÎ¶¨Îüâ: 0.0 req/s
   ÏóêÎü¨ Î∂ÑÎ•ò:
     validation: 0
     transient: 0
     system: 18

‚úÖ ÏûÑÍ≥ÑÍ∞í Í≤ÄÏ¶ù:
   Ï†ÑÏ≤¥ ÏÑ±Í≥µÎ•† ‚ùå 0.640 < 0.9
   Í∞ÄÏö©ÏÑ± ÏÑ±Í≥µÎ•† ‚ùå 0.640 < 0.95
   p95 ÏßÄÏó∞ ‚úÖ 10.95ms <= 20ms

üéâ Phase 4B Îç∞Î™® ÏôÑÎ£å!
============================================================
